Workbook

Sheet Sommaire
A1: Synthèse de valorisation — MCD
A2: Généré le 21/09/2026
A4: VALORISATION
A5: Prix de marché actuel | B5: ='DCF - Modèle'!B62
A6: Valeur par action — DCF (scénario actif) | B6: ='DCF - Modèle'!B61
A7: Scénario actif | B7: ='DCF - Modèle'!C24
A8: Valeur par action — Comparables (moyenne) | B8: ='Comps - Résultat'!D16
A9: Ratio DCF / marché | B9: ='DCF - Modèle'!B63
A10: WACC | B10: ='DCF - Modèle'!B21
A11: Croissance perpétuelle retenue | B11: ='DCF - Modèle'!E27
A12: Marge d'EBIT retenue | B12: ='DCF - Modèle'!E26
A14: SCÉNARIOS (SNAPSHOT PYTHON)
A15: Bear | B15: 170.58945
A16: Base | B16: 281.35264
A17: Bull | B17: 469.25059
A19: CONSENSUS ANALYSTES
A20: Prix cible moyen | B20: 311.5484
A21: Range analystes (low - high) | B21: 250.00 - 407.00
A22: Nombre d'analystes | B22: 31
A23: Recommandation | B23: buy
A25: COMPARABLES RETENUS
A26: YUM, QSR, SBUX, WEN, DPZ, CMG, DRI
A28: LÉGENDE
A29: Bleu | B29: Hypothèse modifiable (input)
A30: Noir | B30: Formule calculée
A31: Vert | B31: Lien vers un autre onglet
A32: Jaune | B32: Résultat clé (surligné)

Sheet DCF - Modèle
A1: DCF — MCD
A2: Bleu = hypothèse modifiable | Noir = formule | Jaune = résultat clé
A3: HYPOTHÈSES
A4: Taux sans risque | B4: 0.042 | C4: 10Y US Treasury — U.S. Department of the Treasury (home.treasury.gov/resource-center/data-chart-center/interest-rates) ou FRED, série DGS10.
A5: Prime de risque marché | B5: 0.05 | C5: Equity Risk Premium (US) — Damodaran, NYU Stern (pages.stern.nyu.edu/~adamodar).
A6: Beta | B6: 0.414 | C6: yfinance (5Y monthly vs S&P 500). À recouper avec Bloomberg/Refinitiv si la valeur semble aberrante, ou avec le beta moyen des comparables.
A7: Coût de la dette (avant impôt) | B7: 0.035 | C7: Approximé par le taux d'intérêt moyen sur la dette existante (notes annexes des états financiers) ou le spread de crédit observé.
A8: Taux d'imposition | B8: 0.25 | C8: Taux effectif observé sur les derniers comptes annuels de la société (10-K / 20-F / document d'enregistrement universel).
A9: Market cap (equity, M) | B9: 175664.94
A10: Dette totale (M) | B10: 54814
A11: Dette nette (M) | B11: 54040
A12: Actions en circulation (M) | B12: 707.64155
A13: Capex (% du CA) | B13: 0.08
A14: D&A (% du CA) | B14: 0.06
A15: Variation du BFR (% du CA) | B15: 0.005
A17: WACC (CAPM)
A18: Coût des fonds propres (CAPM) | B18: =B4+B6*B5
A19: Poids Equity | B19: =B9/(B9+B10)
A20: Poids Dette | B20: =1-B19
A21: WACC | B21: =B19*B18+B20*B7*(1-B8)
A23: SCÉNARIO ACTIF
A24: Sélecteur (1 = Bear, 2 = Base, 3 = Bull) | B24: 2 | C24: =CHOOSE(B24,"Bear","Base","Bull")
B25: Bear | C25: Base | D25: Bull | E25: Retenu (actif)
A26: Marge d'EBIT | B26: 0.43965736 | C26: 0.45965736 | D26: 0.47965736 | E26: =CHOOSE($B$24,B26,C26,D26) | F26: Moyenne des 3 derniers exercices (yfinance) (Bear/Bull = delta ± 2% vs Base)
A27: Croissance perpétuelle (g) | B27: 0.01 | C27: 0.02 | D27: 0.03 | E27: =CHOOSE($B$24,B27,C27,D27)
A29: CROISSANCE DU CA PAR SCÉNARIO (%)
A30: Année | B30: N+1 | C30: N+2 | D30: N+3 | E30: N+4 | F30: N+5
A31: Bear | B31: 0 | C31: -0.005 | D31: -0.01 | E31: -0.01 | F31: -0.005
A32: Base | B32: 0.02 | C32: 0.02 | D32: 0.015 | E32: 0.015 | F32: 0.01
A33: Bull | B33: 0.04 | C33: 0.035 | D33: 0.03 | E33: 0.025 | F33: 0.02
A34: Retenue (active) | B34: =CHOOSE($B$24,B31,B32,B33) | C34: =CHOOSE($B$24,C31,C32,C33) | D34: =CHOOSE($B$24,D31,D32,D33) | E34: =CHOOSE($B$24,E31,E32,E33) | F34: =CHOOSE($B$24,F31,F32,F33)
A36: PROJECTION DES FLUX DE TRÉSORERIE DISPONIBLES
A37: CA de référence (dernier exercice, M) | B37: 26885
A38: Année | B38: N+1 | C38: N+2 | D38: N+3 | E38: N+4 | F38: N+5
A39: Revenus (M) | B39: =B37*(1+B34) | C39: =B39*(1+C34) | D39: =C39*(1+D34) | E39: =D39*(1+E34) | F39: =E39*(1+F34)
A40: EBIT (M) | B40: =B39*$E$26 | C40: =C39*$E$26 | D40: =D39*$E$26 | E40: =E39*$E$26 | F40: =F39*$E$26
A41: NOPAT (M) | B41: =B40*(1-$B$8) | C41: =C40*(1-$B$8) | D41: =D40*(1-$B$8) | E41: =E40*(1-$B$8) | F41: =F40*(1-$B$8)
A42: D&A (M) | B42: =B39*$B$14 | C42: =C39*$B$14 | D42: =D39*$B$14 | E42: =E39*$B$14 | F42: =F39*$B$14
A43: Capex (M) | B43: =B39*$B$13 | C43: =C39*$B$13 | D43: =D39*$B$13 | E43: =E39*$B$13 | F43: =F39*$B$13
A44: Variation du BFR (M) | B44: =B39*$B$15 | C44: =C39*$B$15 | D44: =D39*$B$15 | E44: =E39*$B$15 | F44: =F39*$B$15
...

Sheet DCF - Sensibilité
A1: Sensibilité — Valeur par action (scénario actif)
A2: Recalculée par formule à partir de la feuille DCF - Modèle : toute modification des FCF ou du scénario actif s'y répercute automatiquement.
A3: WACC \ g | B3: 0.01 | C3: 0.015 | D3: 0.02 | E3: 0.025 | F3: 0.03
A4: 0.034 | B4: =IFERROR((SUMPRODUCT('DCF - Modèle'!$B$45:$F$45,1/(1+$A4)^'DCF - Modèle'!$B$46:$F$46)+('DCF - Modèle'!$F$45*(1+B$3))/($A4-B$3)/(1+$A4)^'DCF - Modèle'!$F$46-'DCF - Modèle'!$B$11)/'DCF - Modèle'!$B$12,"n/a") | C4: =IFERROR((SUMPRODUCT('DCF - Modèle'!$B$45:$F$45,1/(1+$A4)^'DCF - Modèle'!$B$46:$F$46)+('DCF - Modèle'!$F$45*(1+C$3))/($A4-C$3)/(1+$A4)^'DCF - Modèle'!$F$46-'DCF - Modèle'!$B$11)/'DCF - Modèle'!$B$12,"n/a") | D4: =IFERROR((SUMPRODUCT('DCF - Modèle'!$B$45:$F$45,1/(1+$A4)^'DCF - Modèle'!$B$46:$F$46)+('DCF - Modèle'!$F$45*(1+D$3))/($A4-D$3)/(1+$A4)^'DCF - Modèle'!$F$46-'DCF - Modèle'!$B$11)/'DCF - Modèle'!$B$12,"n/a") | E4: =IFERROR((SUMPRODUCT('DCF - Modèle'!$B$45:$F$45,1/(1+$A4)^'DCF - Modèle'!$B$46:$F$46)+('DCF - Modèle'!$F$45*(1+E$3))/($A4-E$3)/(1+$A4)^'DCF - Modèle'!$F$46-'DCF - Modèle'!$B$11)/'DCF - Modèle'!$B$12,"n/a") | F4: =IFERROR((SUMPRODUCT('DCF - Modèle'!$B$45:$F$45,1/(1+$A4)^'DCF - Modèle'!$B$46:$F$46)+('DCF - Modèle'!$F$45*(1+F$3))/($A4-F$3)/(1+$A4)^'DCF - Modèle'!$F$46-'DCF - Modèle'!$B$11)/'DCF - Modèle'!$B$12,"n/a")
A5: 0.044 | B5: =IFERROR((SUMPRODUCT('DCF - Modèle'!$B$45:$F$45,1/(1+$A5)^'DCF - Modèle'!$B$46:$F$46)+('DCF - Modèle'!$F$45*(1+B$3))/($A5-B$3)/(1+$A5)^'DCF - Modèle'!$F$46-'DCF - Modèle'!$B$11)/'DCF - Modèle'!$B$12,"n/a") | C5: =IFERROR((SUMPRODUCT('DCF - Modèle'!$B$45:$F$45,1/(1+$A5)^'DCF - Modèle'!$B$46:$F$46)+('DCF - Modèle'!$F$45*(1+C$3))/($A5-C$3)/(1+$A5)^'DCF - Modèle'!$F$46-'DCF - Modèle'!$B$11)/'DCF - Modèle'!$B$12,"n/a") | D5: =IFERROR((SUMPRODUCT('DCF - Modèle'!$B$45:$F$45,1/(1+$A5)^'DCF - Modèle'!$B$46:$F$46)+('DCF - Modèle'!$F$45*(1+D$3))/($A5-D$3)/(1+$A5)^'DCF - Modèle'!$F$46-'DCF - Modèle'!$B$11)/'DCF - Modèle'!$B$12,"n/a") | E5: =IFERROR((SUMPRODUCT('DCF - Modèle'!$B$45:$F$45,1/(1+$A5)^'DCF - Modèle'!$B$46:$F$46)+('DCF - Modèle'!$F$45*(1+E$3))/($A5-E$3)/(1+$A5)^'DCF - Modèle'!$F$46-'DCF - Modèle'!$B$11)/'DCF - Modèle'!$B$12,"n/a") | F5: =IFERROR((SUMPRODUCT('DCF - Modèle'!$B$45:$F$45,1/(1+$A5)^'DCF - Modèle'!$B$46:$F$46)+('DCF - Modèle'!$F$45*(1+F$3))/($A5-F$3)/(1+$A5)^'DCF - Modèle'!$F$46-'DCF - Modèle'!$B$11)/'DCF - Modèle'!$B$12,"n/a")
A6: 0.054 | B6: =IFERROR((SUMPRODUCT('DCF - Modèle'!$B$45:$F$45,1/(1+$A6)^'DCF - Modèle'!$B$46:$F$46)+('DCF - Modèle'!$F$45*(1+B$3))/($A6-B$3)/(1+$A6)^'DCF - Modèle'!$F$46-'DCF - Modèle'!$B$11)/'DCF - Modèle'!$B$12,"n/a") | C6: =IFERROR((SUMPRODUCT('DCF - Modèle'!$B$45:$F$45,1/(1+$A6)^'DCF - Modèle'!$B$46:$F$46)+('DCF - Modèle'!$F$45*(1+C$3))/($A6-C$3)/(1+$A6)^'DCF - Modèle'!$F$46-'DCF - Modèle'!$B$11)/'DCF - Modèle'!$B$12,"n/a") | D6: =IFERROR((SUMPRODUCT('DCF - Modèle'!$B$45:$F$45,1/(1+$A6)^'DCF - Modèle'!$B$46:$F$46)+('DCF - Modèle'!$F$45*(1+D$3))/($A6-D$3)/(1+$A6)^'DCF - Modèle'!$F$46-'DCF - Modèle'!$B$11)/'DCF - Modèle'!$B$12,"n/a") | E6: =IFERROR((SUMPRODUCT('DCF - Modèle'!$B$45:$F$45,1/(1+$A6)^'DCF - Modèle'!$B$46:$F$46)+('DCF - Modèle'!$F$45*(1+E$3))/($A6-E$3)/(1+$A6)^'DCF - Modèle'!$F$46-'DCF - Modèle'!$B$11)/'DCF - Modèle'!$B$12,"n/a") | F6: =IFERROR((SUMPRODUCT('DCF - Modèle'!$B$45:$F$45,1/(1+$A6)^'DCF - Modèle'!$B$46:$F$46)+('DCF - Modèle'!$F$45*(1+F$3))/($A6-F$3)/(1+$A6)^'DCF - Modèle'!$F$46-'DCF - Modèle'!$B$11)/'DCF - Modèle'!$B$12,"n/a")
A7: 0.064 | B7: =IFERROR((SUMPRODUCT('DCF - Modèle'!$B$45:$F$45,1/(1+$A7)^'DCF - Modèle'!$B$46:$F$46)+('DCF - Modèle'!$F$45*(1+B$3))/($A7-B$3)/(1+$A7)^'DCF - Modèle'!$F$46-'DCF - Modèle'!$B$11)/'DCF - Modèle'!$B$12,"n/a") | C7: =IFERROR((SUMPRODUCT('DCF - Modèle'!$B$45:$F$45,1/(1+$A7)^'DCF - Modèle'!$B$46:$F$46)+('DCF - Modèle'!$F$45*(1+C$3))/($A7-C$3)/(1+$A7)^'DCF - Modèle'!$F$46-'DCF - Modèle'!$B$11)/'DCF - Modèle'!$B$12,"n/a") | D7: =IFERROR((SUMPRODUCT('DCF - Modèle'!$B$45:$F$45,1/(1+$A7)^'DCF - Modèle'!$B$46:$F$46)+('DCF - Modèle'!$F$45*(1+D$3))/($A7-D$3)/(1+$A7)^'DCF - Modèle'!$F$46-'DCF - Modèle'!$B$11)/'DCF - Modèle'!$B$12,"n/a") | E7: =IFERROR((SUMPRODUCT('DCF - Modèle'!$B$45:$F$45,1/(1+$A7)^'DCF - Modèle'!$B$46:$F$46)+('DCF - Modèle'!$F$45*(1+E$3))/($A7-E$3)/(1+$A7)^'DCF - Modèle'!$F$46-'DCF - Modèle'!$B$11)/'DCF - Modèle'!$B$12,"n/a") | F7: =IFERROR((SUMPRODUCT('DCF - Modèle'!$B$45:$F$45,1/(1+$A7)^'DCF - Modèle'!$B$46:$F$46)+('DCF - Modèle'!$F$45*(1+F$3))/($A7-F$3)/(1+$A7)^'DCF - Modèle'!$F$46-'DCF - Modèle'!$B$11)/'DCF - Modèle'!$B$12,"n/a")
A8: 0.074 | B8: =IFERROR((SUMPRODUCT('DCF - Modèle'!$B$45:$F$45,1/(1+$A8)^'DCF - Modèle'!$B$46:$F$46)+('DCF - Modèle'!$F$45*(1+B$3))/($A8-B$3)/(1+$A8)^'DCF - Modèle'!$F$46-'DCF - Modèle'!$B$11)/'DCF - Modèle'!$B$12,"n/a") | C8: =IFERROR((SUMPRODUCT('DCF - Modèle'!$B$45:$F$45,1/(1+$A8)^'DCF - Modèle'!$B$46:$F$46)+('DCF - Modèle'!$F$45*(1+C$3))/($A8-C$3)/(1+$A8)^'DCF - Modèle'!$F$46-'DCF - Modèle'!$B$11)/'DCF - Modèle'!$B$12,"n/a") | D8: =IFERROR((SUMPRODUCT('DCF - Modèle'!$B$45:$F$45,1/(1+$A8)^'DCF - Modèle'!$B$46:$F$46)+('DCF - Modèle'!$F$45*(1+D$3))/($A8-D$3)/(1+$A8)^'DCF - Modèle'!$F$46-'DCF - Modèle'!$B$11)/'DCF - Modèle'!$B$12,"n/a") | E8: =IFERROR((SUMPRODUCT('DCF - Modèle'!$B$45:$F$45,1/(1+$A8)^'DCF - Modèle'!$B$46:$F$46)+('DCF - Modèle'!$F$45*(1+E$3))/($A8-E$3)/(1+$A8)^'DCF - Modèle'!$F$46-'DCF - Modèle'!$B$11)/'DCF - Modèle'!$B$12,"n/a") | F8: =IFERROR((SUMPRODUCT('DCF - Modèle'!$B$45:$F$45,1/(1+$A8)^'DCF - Modèle'!$B$46:$F$46)+('DCF - Modèle'!$F$45*(1+F$3))/($A8-F$3)/(1+$A8)^'DCF - Modèle'!$F$46-'DCF - Modèle'!$B$11)/'DCF - Modèle'!$B$12,"n/a")

Sheet Comps - Peers
A1: Comparables boursiers
A3: Ticker | B3: Nom | C3: Market Cap (M) | D3: EV (M) | E3: P/E | F3: Fwd P/E | G3: EV/EBITDA | H3: EV/Sales
A4: YUM | B4: Yum! Brands, Inc. | C4: 37657.625 | D4: 50388.619 | E4: 17.40101 | F4: 19.723001 | G4: 16.424 | H4: 5.777
A5: QSR | B5: Restaurant Brands International | C5: 33387.127 | D5: 41511.49 | E5: 18.311558 | F5: 16.446196 | G5: 14.197 | H5: 4.28
A6: SBUX | B6: Starbucks Corporation | C6: 109246.2 | D6: 128096.2 | E6: 55.393063 | F6: 30.687695 | G6: 22.703 | H6: 3.341
A7: WEN | B7: Wendy's Company (The) | C7: 1285.1153 | D7: 5016.4296 | E7: 10.21212 | F7: 12.911877 | G7: 11.002 | H7: 2.276
A8: DPZ | B8: Domino's Pizza Inc | C8: 9732.6469 | D8: 14690.663 | E8: 16.668556 | F8: 14.104143 | G8: 14.353 | H8: 2.922
A9: CMG | B9: Chipotle Mexican Grill, Inc. | C9: 42302.923 | D9: 47044.264 | E9: 30.953703 | F9: 24.398611 | G9: 20.679 | H9: 3.787
A10: DRI | B10: Darden Restaurants, Inc. | C10: 23762.02 | D10: 31701.238 | E10: 20.045979 | F10: 16.881163 | G10: 14.989 | H10: 2.4
A12: Source : yfinance, données de marché à la date d'exécution du script.

Sheet Comps - Résultat
A1: Valorisation par comparables
A3: Métriques de la cible (M)
A4: Revenue (M) | B4: 26885
A5: EBITDA (M) | B5: 14678
A6: Net income (M) | B6: 8563
A8: Dette nette (M) | B8: ='DCF - Modèle'!$B$11
A9: Actions en circulation (M) | B9: ='DCF - Modèle'!$B$12
A12: Méthode | B12: Multiple médian peers | C12: Valeur implicite (M) | D12: Valeur par action implicite
A13: EV/EBITDA | B13: =MEDIAN('Comps - Peers'!G:G) | C13: =B13*$B$5 | D13: =(C13-$B$8)/$B$9
A14: EV/Sales | B14: =MEDIAN('Comps - Peers'!H:H) | C14: =B14*$B$4 | D14: =(C14-$B$8)/$B$9
A15: P/E | B15: =MEDIAN('Comps - Peers'!E:E) | C15: =B15*$B$6 | D15: =C15/$B$9
A16: Moyenne des méthodes | D16: =AVERAGE(D13:D15)

Sheet Football Field
A1: Football Field — Fourchettes de valorisation
A2: Snapshot calculé à la génération du script à partir des scénarios Bear/Bull du DCF, du min-max des comparables et du range 52 semaines.
A4: Méthode | B4: Low | C4: Range | D4: High
A5: DCF (Bear-Bull) | B5: 170.58945 | C5: =D5-B5 | D5: 469.25059
A6: Comparables (min-max) | B6: 50.566258 | C6: =D6-B6 | D6: 234.53759
A7: 52 semaines (marché) | B7: 247.65 | C7: =D7-B7 | D7: 341.75
A8: Prix de marché actuel | B8: 246.9988 | C8: =D8-B8 | D8: 249.4812

Sheet Compte de résultat
A1: Compte de résultat — en millions USD
A3: Poste | B3: 2022 | C3: 2023 | D3: 2024 | E3: 2025
A4: Tax Effect Of Unusual Items | B4: -201.083 | C4: -45.435 | D4: -62.123055 | E4: -49.905662
A5: Tax Rate For Calcs | B5: 2.11e-07 | C5: 1.95e-07 | D5: 2.05027e-07 | E5: 2.14187e-07
A6: Normalized EBITDA | B6: 11856 | C6: 14094 | D6: 14251 | E6: 14911
A7: Total Unusual Items | B7: -953 | C7: -233 | D7: -303 | E7: -233
A8: Total Unusual Items Excluding Goodwill | B8: -953 | C8: -233 | D8: -303 | E8: -233
A9: Net Income From Continuing Operation Net Minority Interest | B9: 6177 | C9: 8469 | D9: 8223 | E9: 8563
A10: Reconciled Depreciation | B10: 1871 | C10: 1978 | D10: 2097 | E10: 2199
A11: Reconciled Cost Of Revenue | B11: 8474 | C11: 9335 | D11: 9560 | E11: 9709
A12: EBITDA | B12: 10903 | C12: 13861 | D12: 13948 | E12: 14678
A13: EBIT | B13: 9032 | C13: 11883 | D13: 11851 | E13: 12479
A14: Net Interest Income | B14: -1163 | C14: -1174 | D14: -1403 | E14: -1500
A15: Interest Expense | B15: 1207 | C15: 1361 | D15: 1506 | E15: 1582
... A38: Write Off | B38: 1010 | C38: 362 | D38: 291 | E38: 229
A39: Restructuring And Mergern Acquisition | D39: 221
A40: Earnings From Equity Interest | B40: 113 | C40: 153 | D40: 157 | E40: 190
A41: Gain On Sale Of Security | B41: 134 | C41: 19 | D41: -6 | E41: -40
A42: Net Non Operating Interest Income Expense | B42: -1163 | C42: -1174 | D42: -1403 | E42: -1500
A43: Interest Expense Non Operating | B43: 1207 | C43: 1361 | D43: 1506 | E43: 1582
A44: Interest Income Non Operating | B44: 44 | C44: 187 | D44: 103 | E44: 82
A45: Operating Income | B45: 10345 | C45: 11747 | D45: 11851 | E45: 12394
A46: Operating Expense | B46: 2862 | C46: 2817 | D46: 2859 | E46: 3040
A47: Depreciation Amortization Depletion Income Statement | B47: 370 | C47: 382 | D47: 447 | E47: 457
A48: Depreciation And Amortization In Income Statement | B48: 370 | C48: 382 | D48: 447 | E48: 457
A49: Selling General And Administration | B49: 2492 | C49: 2435 | D49: 2412 | E49: 2583
A50: Gross Profit | B50: 13207 | C50: 14564 | D50: 14710 | E50: 15434
A51: Cost Of Revenue | B51: 9975 | C51: 10931 | D51: 11210 | E51: 11451
... A53: Operating Revenue | B53: 22854 | C53: 25179 | D53: 25497 | E53: 26238
A55: Source : yfinance — à recouper avec les états financiers officiels (10-K / 20-F / document d'enregistrement universel).

Sheet Bilan
A1: Bilan — en millions USD
A3: Poste | B3: 2021 | C3: 2022 | D3: 2023 | E3: 2024 | F3: 2025
A4: Treasury Shares Number | C4: 929.3 | D4: 937.9 | E4: 945.4 | F4: 950
A5: Ordinary Shares Number | C5: 731.3 | D5: 722.7 | E5: 715.2 | F5: 710.6
A6: Share Issued | C6: 1660.6 | D6: 1660.6 | E6: 1660.6 | F6: 1660.6
A7: Net Debt | C7: 33319.7 | D7: 34766 | E7: 37339 | F7: 39199
A8: Total Debt | C8: 48699 | D8: 53091 | E8: 51948 | F8: 54814
A9: Tangible Book Value | C9: -8903.8 | D9: -7746 | E9: -6941 | F9: -5144
A10: Invested Capital | C10: 29900.1 | D10: 34639 | E10: 34628 | F10: 38183
A11: Working Capital | C11: 1622.1 | D11: 1127 | E11: 738 | F11: -198
A12: Net Tangible Assets | C12: -8903.8 | D12: -7746 | E12: -6941 | F12: -5144
A13: Capital Lease Obligations | C13: 12795.5 | D13: 13746 | E13: 13524 | F13: 14841
A14: Common Stock Equity | C14: -6003.4 | D14: -4706 | E14: -3796 | F14: -1790
A15: Total Capitalization | C15: 29900.1 | D15: 32447 | E15: 34628 | F15: 38183
... A38: Current Capital Lease Obligation | C38: 661.1 | D38: 688 | E38: 636 | F38: 694
A39: Current Debt | D39: 2192
A40: Other Current Borrowings | D40: 2192
A41: Payables And Accrued Expenses | C41: 3141 | D41: 3979 | E41: 3225 | F41: 3667
A42: Current Accrued Expenses | C42: 1630.8 | D42: 1903 | E42: 1611 | F42: 2021
A43: Interest Payable | C43: 393.4 | D43: 469 | E43: 482 | F43: 533
A44: Payables | C44: 1510.2 | D44: 2076 | E44: 1614 | F44: 1646
A45: Total Tax Payable | C45: 530 | D45: 973 | E45: 585 | F45: 497
A46: Income Tax Payable | C46: 274.9 | D46: 705 | E46: 361 | F46: 250
A47: Accounts Payable | C47: 980.2 | D47: 1103 | E47: 1029 | F47: 1149
A48: Total Assets | C48: 50435.6 | D48: 56147 | E48: 55182 | F48: 59515
A49: Total Non Current Assets | C49: 45011.4 | D49: 48159 | E49: 50584 | F49: 55352
A50: Other Non Current Assets | C50: 4707.2 | D50: 5618 | E50: 6095 | F50: 6331
A51: Investments And Advances | C51: 1064.5 | D51: 1080 | E51: 2710 | F51: 2820
A52: Long Term Equity Investment | C52: 1064.5 | D52: 1080 | E52: 2710 | F52: 2820
A53: Investmentsin Associatesat Cost | B53: 1201.2 | C53: 1064.5
A54: Goodwill And Other Intangible Assets | C54: 2900.4 | D54: 3040 | E54: 3145 | F54: 3354
A55: Goodwill | C55: 2900.4 | D55: 3040 | E55: 3145 | F55: 3354
A56: Net PPE | C56: 36339.3 | D56: 38421 | E56: 38634 | F56: 42847
A57: Accumulated Depreciation | C57: -17264 | D57: -18662 | E57: -18882 | F57: -21049
A58: Gross PPE | C58: 53603.3 | D58: 57083 | E58: 57516 | F58: 63896
A59: Other Properties | C59: 15490.8 | D59: 16621 | E59: 16359 | F59: 18019
A60: Machinery Furniture Equipment | B60: 3032 | C60: 2498.6
A61: Buildings And Improvements | C61: 31426.2 | D61: 33381 | E61: 33904 | F61: 37708
A62: Land And Improvements | C62: 6686.3 | D62: 7081 | E62: 7253 | F62: 8169
A63: Properties | C63: 0 | D63: 0 | E63: 0 | F63: 0
...

Sheet Cash-flow
A1: Cash-flow — en millions USD
A3: Poste | B3: 2021 | C3: 2022 | D3: 2023 | E3: 2024 | F3: 2025
A4: Free Cash Flow | C4: 5488 | D4: 7255 | E4: 6672 | F4: 7186
A5: Repurchase Of Capital Stock | C5: -3896 | D5: -3054 | E5: -2824 | F5: -2056
A6: Repayment Of Debt | C6: -2202 | D6: -2441 | E6: -2777 | F6: -4802
A7: Issuance Of Debt | C7: 3374 | D7: 5221 | E7: 2380 | F7: 4724
A8: Capital Expenditure | C8: -1899 | D8: -2357 | E8: -2775 | F8: -3365
A9: Interest Paid Supplemental Data | C9: 1184 | D9: 1287 | E9: 1523 | F9: 1555
A10: Income Tax Paid Supplemental Data | B10: 2403.9 | C10: 3024 | D10: 2992.9 | E10: 2974
A11: End Cash Position | C11: 2584 | D11: 4579 | E11: 1085 | F11: 774
A12: Beginning Cash Position | C12: 4709 | D12: 2584 | E12: 4579 | F12: 1085
A13: Effect Of Exchange Rate Changes | C13: -254 | D13: -58 | E13: -101 | F13: 86
A14: Changes In Cash | C14: -1871 | D14: 2053 | E14: -3393 | F14: -397
A15: Financing Cash Flow | C15: -6580 | D15: -4374 | E15: -7495 | F15: -7125
A16: Cash Flow From Continuing Financing Activities | C16: -6580 | D16: -4374 | E16: -7493 | F16: -7125
A17: Net Other Financing Charges | C17: 38 | D17: -40 | E17: -58 | F17: -167
A18: Proceeds From Stock Option Exercised | C18: 248 | D18: 260 | E18: 328 | F18: 285
A19: Cash Dividends Paid | C19: -4168 | D19: -4533 | E19: -4870 | F19: -5115
A20: Common Stock Dividend Paid | C20: -4168 | D20: -4533 | E20: -4870 | F20: -5115
A21: Net Common Stock Issuance | C21: -3896 | D21: -3054 | E21: -2824 | F21: -2056
A22: Common Stock Payments | C22: -3896 | D22: -3054 | E22: -2824 | F22: -2056
... A39: Change In Working Capital | C39: -645 | D39: -108 | E39: -438 | F39: 106
A40: Change In Other Working Capital | B40: -302.5 | C40: -546.7 | D40: -220.3
A41: Change In Payables And Accrued Expense | C41: -387 | D41: 36 | E41: -519 | F41: 15
A42: Change In Accrued Expense | C42: 129 | D42: 206 | E42: -217 | F42: 154
A43: Change In Payable | C43: -516 | D43: -170 | E43: -302 | F43: -139
A44: Change In Account Payable | C44: 31 | D44: 50 | E44: -10 | F44: 100
A45: Change In Tax Payable | C45: -547 | D45: -220 | E45: -292 | F45: -239
A46: Change In Income Tax Payable | C46: -547 | D46: -220 | E46: -292 | F46: -239
A47: Change In Inventory | C47: 6 | D47: 17 | E47: 71 | F47: -140
A48: Change In Receivables | C48: -264 | D48: -161 | E48: 10 | F48: 231
A49: Changes In Account Receivables | C49: -264 | D49: -161 | E49: 10 | F49: 231
A50: Other Non Cash Items | C50: -570 | D50: -113 | E50: 4 | F50: -207
A51: Stock Based Compensation | C51: 167 | D51: 175 | E51: 172 | F51: 165
A52: Deferred Tax | C52: -346 | D52: -686 | E52: -574 | F52: -126
... A58: Net Income From Continuing Operations | C58: 6177 | D58: 8469 | E58: 8223 | F58: 8563
A60: Source : yfinance — à recouper avec les états financiers officiels (10-K / 20-F / document d'enregistrement universel).
